<?xml version="1.0"?>
<!--
Software License Agreement (BSD)

\file      d46.urdf.xacro
\authors   Arnold <akalmbach@clearpathrobotics.com>
\copyright Copyright (c) 2014, Clearpath Robotics, Inc., All rights reserved.

Redistribution and use in source and binary forms, with or without modification, are permitted provided that
the following conditions are met:
 * Redistributions of source code must retain the above copyright notice, this list of conditions and the
   following disclaimer.
 * Redistributions in binary form must reproduce the above copyright notice, this list of conditions and the 
   following disclaimer in the documentation and/or other materials provided with the distribution.
 * Neither the name of Clearpath Robotics nor the names of its contributors may be used to endorse or promote
   products derived from this software without specific prior written permission.

THIS SOFTWARE IS PROVIDED BY THE COPYRIGHT HOLDERS AND CONTRIBUTORS "AS IS" AND ANY EXPRESS OR IMPLIED WAR-
RANTIES, INCLUDING, BUT NOT LIMITED TO, THE IMPLIED WARRANTIES OF MERCHANTABILITY AND FITNESS FOR A PARTICULAR
PURPOSE ARE DISCLAIMED. IN NO EVENT SHALL THE COPYRIGHT HOLDER OR CONTRIBUTORS BE LIABLE FOR ANY DIRECT, IN-
DIRECT, INCIDENTAL, SPECIAL, EXEMPLARY, OR CONSEQUENTIAL DAMAGES (INCLUDING, BUT NOT LIMITED TO, PROCUREMENT
OF SUBSTITUTE GOODS OR SERVICES; LOSS OF USE, DATA, OR PROFITS; OR BUSINESS INTERRUPTION) HOWEVER CAUSED AND
ON ANY THEORY OF LIABILITY, WHETHER IN CONTRACT, STRICT LIABILITY, OR TORT (INCLUDING NEGLIGENCE OR OTHERWISE)
ARISING IN ANY WAY OUT OF THE USE OF THIS SOFTWARE, EVEN IF ADVISED OF THE POSSIBILITY OF SUCH DAMAGE.
-->
<robot name="ptu_d46"
       xmlns:xacro="http://ros.org/wiki/xacro">
  <xacro:property name="pan_velocity" value="1.0" />
  <xacro:property name="pan_range" value="2.775" />
  <xacro:property name="tilt_velocity" value="1.0" />
  <xacro:property name="tilt_up_range" value="0.82" />
  <xacro:property name="tilt_down_range" value="0.52" />
  <xacro:property name="joint_effort" value="30" />
    
  <xacro:macro name="ptu_d46" params="name">

    <link name="${name}_base_link">
       <visual>
            <origin xyz="0 0 0" rpy="0 0 0" />
            <geometry>
                <box size="0.001 0.001 0.001" />
            </geometry>
        </visual>
       <collision>
            <origin xyz="0 0 0" rpy="0 0 0" />
            <geometry>
                <box size="0.001 0.001 0.001" />
            </geometry>
       </collision>
       <inertial>
            <origin xyz="0 0 0" rpy="0 0 0"/>
            <mass value="1.0"/>
            <inertia ixx="0.01" ixy="0" ixz="0" iyy="0.01" iyz="0" izz="0.01" />
       </inertial>
    </link>
    
    <!-- There's an offset between the origin of the pan joint and the origin of 
     the overall device, which is between the mounting screws on its base. -->
    <joint name="${name}_base" type="fixed">
      <parent link="${name}_base_link"/>
      <child link="${name}_pan_link"/>
      <origin xyz="0 -0.011 0.022" rpy="0 -1.5708 0"/>
    </joint>
    
    <link name="${name}_pan_link">
        <inertial>
            <origin xyz="0 0 0" rpy="0 0 0"/>
            <mass value="1.0"/>
            <inertia ixx="0.01" ixy="0" ixz="0" iyy="0.01" iyz="0" izz="0.01" />
        </inertial>
        <visual>
            <material name="ptu_body_color">
                <color rgba="0.3 0.3 0.3 1.0" />
            </material>
            <geometry>
                <box size="0.045 0.065 0.044" />
            </geometry>
            <origin xyz="0 0.011 0" />
        </visual>
    </link>

    <joint name="${name}_pan" type="revolute">
      <parent link="${name}_pan_link" />
      <origin xyz="0 0 0.066" rpy="-1.5708 0 0" />
      <child link="${name}_tilt_link" />
      <axis xyz="0 -1 0" rpy="3.14159 0 0" />
      <limit lower="${-pan_range}" upper="${pan_range}"
             effort="${joint_effort}" velocity="${pan_velocity}" />
    </joint>

    <link name="${name}_tilt_link">
        <inertial>
            <origin xyz="0 0 0" rpy="0 0 0"/>
            <mass value="1.0"/>
            <inertia ixx="0.01" ixy="0" ixz="0" iyy="0.01" iyz="0" izz="0.01" />
        </inertial>
        <visual>
            <material name="ptu_body_color">
                <color rgba="0.3 0.3 0.3 1.0" />
            </material>
            <geometry>
                <box size="0.045 0.065 0.044" />
            </geometry>
            <origin xyz="0 0.011 0" />
        </visual>
    </link>
    
    <joint name="${name}_tilt" type="revolute">
      <parent link="${name}_tilt_link" />
      <origin xyz="0 0 0" rpy="-1.5708 0 0" />
      <child link="${name}_tilted_link" />
      <axis xyz="0 1 0" />
      <limit lower="${-tilt_down_range}" upper="${tilt_up_range}"
             effort="${joint_effort}" velocity="${tilt_velocity}" />
    </joint>
    
    <link name="${name}_tilted_link">
       <visual>
            <origin xyz="0 0 0" rpy="0 0 0" />
            <geometry>
                <box size="0.001 0.001 0.001" />
            </geometry>
        </visual>
       <collision>
            <origin xyz="0 0 0" rpy="0 0 0" />
            <geometry>
                <box size="0.001 0.001 0.001" />
            </geometry>
       </collision>
       <inertial>
            <origin xyz="0 0 0" rpy="0 0 0"/>
            <mass value="1.0"/>
            <inertia ixx="0.01" ixy="0" ixz="0" iyy="0.01" iyz="0" izz="0.01" />
       </inertial>  
    </link>
    
    <joint name="${name}_mount" type="fixed">
      <parent link="${name}_tilted_link"/>
      <child link="${name}_mount_link"/>
      <origin xyz="0 0 -0.03912" rpy="3.1416 0 0" />
    </joint>
    
    <link name="${name}_mount_link">
       <visual>
            <origin xyz="0 0 0" rpy="0 0 0" />
            <geometry>
                <box size="0.001 0.001 0.001" />
            </geometry>
        </visual>
       <collision>
            <origin xyz="0 0 0" rpy="0 0 0" />
            <geometry>
                <box size="0.001 0.001 0.001" />
            </geometry>
       </collision>
       <inertial>
            <origin xyz="0 0 0" rpy="0 0 0"/>
            <mass value="1.0"/>
            <inertia ixx="0.01" ixy="0" ixz="0" iyy="0.01" iyz="0" izz="0.01" />
       </inertial>
    </link>

  </xacro:macro>
</robot>
